Workbook
Name Slicer_Attendance__Performance: #N/A
Name Slicer_Career__Aspiration: #N/A
Name Slicer_Extracurricular__Activities: #N/A
Name Slicer_Gender: #N/A
Name Slicer_Part_Time__Job: #N/A

Sheet Data
A1: ID | B1: First Name | C1: Last Name | D1: Full Name | E1: Email | F1: Gender | G1: Part Time Job | H1: Absence Days | I1: Extracurricular Activities | J1: Self Study Hours | K1: Career Aspiration | L1: Math Score | M1: Math Grade | N1: History Score | O1: History Grade | P1: Physics Score | Q1: Physics Grade | R1: Chemistry Score | S1: Chemistry Grade | T1: Biology Score | U1: Biology Grade | V1: English Score | W1: English Grade | X1: Geography Score | Y1: Geography Grade | Z1: Total Score | AA1: Average Score | AB1: Overall Grade | AC1: Ranking | AD1: Attendance Performance
A2: 1 | B2: Paul | C2: Casey | D2: =_xlfn.TEXTJOIN(" ",TRUE,Table1[[#This Row],[First Name]:[Last Name]]) -> Paul Casey | E2: paul.casey.1@gslingacademy.com | F2: Male | G2: =PROPER(Table1[[#This Row],[Part Time Job]]) -> False | H2: 3 | I2: =PROPER(Table1[[#This Row],[Extracurricular Activities]]) -> False | J2: 27 | K2: Lawyer | L2: 73 | M2: {=_xlfn.IFS(Table1[[#This Row],[Math Score]]>=90,"A+",Table1[[#This Row],[Math Score]]>=80,"A", Table1[[#This Row],[Math Score]]>=75,"A-",Table1[[#This Row],[Math Score]]>=70,"B+",Table1[[#This Row],[Math Score]]>=65,"B",Table1[[#This Row],[Math Score]]>=60,"B-",Table1[[#This Row],[Math Score]]>=50,"C",Table1[[#This Row],[Math Score]]>=40,"D",Table1[[#This Row],[Math Score]]<40,"F")} -> B+ | N2: 81 | O2: {=_xlfn.IFS(Table1[[#This Row],[History Score]]>=90,"A+",Table1[[#This Row],[History Score]]>=80,"A", Table1[[#This Row],[History Score]]>=75,"A-",Table1[[#This Row],[History Score]]>=70,"B+",Table1[[#This Row],[History Score]]>=65,"B",Table1[[#This Row],[History Score]]>=60,"B-",Table1[[#This Row],[History Score]]>=50,"C",Table1[[#This Row],[History Score]]>=40,"D",Table1[[#This Row],[History Score]]<40,"F")} -> A | P2: 93 | Q2: {=_xlfn.IFS(Table1[[#This Row],[Physics Score]]>=90,"A+",Table1[[#This Row],[Physics Score]]>=80,"A", Table1[[#This Row],[Physics Score]]>=75,"A-",Table1[[#This Row],[Physics Score]]>=70,"B+",Table1[[#This Row],[Physics Score]]>=65,"B",Table1[[#This Row],[Physics Score]]>=60,"B-",Table1[[#This Row],[Physics Score]]>=50,"C",Table1[[#This Row],[Physics Score]]>=40,"D",Table1[[#This Row],[Physics Score]]<40,"F")} -> A+ | R2: 97 | S2: {=_xlfn.IFS(Table1[[#This Row],[Chemistry Score]]>=90,"A+",Table1[[#This Row],[Chemistry Score]]>=80,"A", Table1[[#This Row],[Chemistry Score]]>=75,"A-",Table1[[#This Row],[Chemistry Score]]>=70,"B+",Table1[[#This Row],[Chemistry Score]]>=65,"B",Table1[[#This Row],[Chemistry Score]]>=60,"B-",Table1[[#This Row],[Chemistry Score]]>=50,"C",Table1[[#This Row],[Chemistry Score]]>=40,"D",Table1[[#This Row],[Chemistry Score]]<40,"F")} -> A+ | T2: 63 | U2: {=_xlfn.IFS(Table1[[#This Row],[Biology Score]]>=90,"A+",Table1[[#This Row],[Biology Score]]>=80,"A", Table1[[#This Row],[Biology Score]]>=75,"A-",Table1[[#This Row],[Biology Score]]>=70,"B+",Table1[[#This Row],[Biology Score]]>=65,"B",Table1[[#This Row],[Biology Score]]>=60,"B-",Table1[[#This Row],[Biology Score]]>=50,"C",Table1[[#This Row],[Biology Score]]>=40,"D",Table1[[#This Row],[Biology Score]]<40,"F")} -> B- | V2: 80 | W2: {=_xlfn.IFS(Table1[[#This Row],[English Score]]>=90,"A+",Table1[[#This Row],[English Score]]>=80,"A", Table1[[#This Row],[English Score]]>=75,"A-",Table1[[#This Row],[English Score]]>=70,"B+",Table1[[#This Row],[English Score]]>=65,"B",Table1[[#This Row],[English Score]]>=60,"B-",Table1[[#This Row],[English Score]]>=50,"C",Table1[[#This Row],[English Score]]>=40,"D",Table1[[#This Row],[English Score]]<40,"F")} -> A | X2: 87 | Y2: {=_xlfn.IFS(Table1[[#This Row],[Geography Score]]>=90,"A+",Table1[[#This Row],[Geography Score]]>=80,"A", Table1[[#This Row],[Geography Score]]>=75,"A-",Table1[[#This Row],[Geography Score]]>=70,"B+",Table1[[#This Row],[Geography Score]]>=65,"B",Table1[[#This Row],[Geography Score]]>=60,"B-",Table1[[#This Row],[Geography Score]]>=50,"C",Table1[[#This Row],[Geography Score]]>=40,"D",Table1[[#This Row],[Geography Score]]<40,"F")} -> A | Z2: =SUM(Table1[[#This Row],[Math Score]],Table1[[#This Row],[History Score]],Table1[[#This Row],[Physics Score]],Table1[[#This Row],[Chemistry Score]],Table1[[#This Row],[Biology Score]],Table1[[#This Row],[English Score]],Table1[[#This Row],[Geography Score]]) -> 574 | AA2: =AVERAGE(Table1[[#This Row],[Math Score]],Table1[[#This Row],[History Score]],Table1[[#This Row],[Physics Score]],Table1[[#This Row],[Chemistry Score]],Table1[[#This Row],[Biology Score]],Table1[[#This Row],[English Score]],Table1[[#This Row],[Geography Score]]) -> 82 | AB2: =_xlfn.IFS(Table1[[#This Row],[Average Score]]>=90,"A+",Table1[[#This Row],[Average Score]]>=80,"A", Table1[[#This Row],[Average Score]]>=75,"A-",Table1[[#This Row],[Average Score]]>=70,"B+",Table1[[#This Row],[Average Score]]>=65,"B",Table1[[#This Row],[Average Score]]>=60,"B-",Table1[[#This Row],[Average Score]]>=50,"C",Table1[[#This Row],[Average Score]]>=40,"D",Table1[[#This Row],[Average Score]]<40,"F") -> A | AC2: =RANK(AA2,$AA$2:$AA$2001,0) -> 832 | AD2: =_xlfn.IFS(Table1[[#This Row],[Absence Days]]<3,"Excellent",Table1[[#This Row],[Absence Days]]<=6,"Good",Table1[[#This Row],[Absence Days]]>6,"Poor") -> Good
A3: 2 | B3: Danielle | C3: Sandoval | D3: =_xlfn.TEXTJOIN(" ",TRUE,Table1[[#This Row],[First Name]:[Last Name]]) -> Danielle Sandoval | E3: danielle.sandoval.2@gslingacademy.com | F3: Female | G3: =PROPER(Table1[[#This Row],[Part Time Job]]) -> False | H3: 2 | I3: =PROPER(Table1[[#This Row],[Extracurricular Activities]]) -> False | J3: 47 | K3: Doctor | L3: 90 | M3: {=_xlfn.IFS(Table1[[#This Row],[Math Score]]>=90,"A+",Table1[[#This Row],[Math Score]]>=80,"A", Table1[[#This Row],[Math Score]]>=75,"A-",Table1[[#This Row],[Math Score]]>=70,"B+",Table1[[#This Row],[Math Score]]>=65,"B",Table1[[#This Row],[Math Score]]>=60,"B-",Table1[[#This Row],[Math Score]]>=50,"C",Table1[[#This Row],[Math Score]]>=40,"D",Table1[[#This Row],[Math Score]]<40,"F")} -> A+ | N3: 86 | O3: {=_xlfn.IFS(Table1[[#This Row],[History Score]]>=90,"A+",Table1[[#This Row],[History Score]]>=80,"A", Table1[[#This Row],[History Score]]>=75,"A-",Table1[[#This Row],[History Score]]>=70,"B+",Table1[[#This Row],[History Score]]>=65,"B",Table1[[#This Row],[History Score]]>=60,"B-",Table1[[#This Row],[History Score]]>=50,"C",Table1[[#This Row],[History Score]]>=40,"D",Table1[[#This Row],[History Score]]<40,"F")} -> A | P3: 96 | Q3: {=_xlfn.IFS(Table1[[#This Row],[Physics Score]]>=90,"A+",Table1[[#This Row],[Physics Score]]>=80,"A", Table1[[#This Row],[Physics Score]]>=75,"A-",Table1[[#This Row],[Physics Score]]>=70,"B+",Table1[[#This Row],[Physics Score]]>=65,"B",Table1[[#This Row],[Physics Score]]>=60,"B-",Table1[[#This Row],[Physics Score]]>=50,"C",Table1[[#This Row],[Physics Score]]>=40,"D",Table1[[#This Row],[Physics Score]]<40,"F")} -> A+ | R3: 100 | S3: {=_xlfn.IFS(Table1[[#This Row],[Chemistry Score]]>=90,"A+",Table1[[#This Row],[Chemistry Score]]>=80,"A", Table1[[#This Row],[Chemistry Score]]>=75,"A-",Table1[[#This Row],[Chemistry Score]]>=70,"B+",Table1[[#This Row],[Chemistry Score]]>=65,"B",Table1[[#This Row],[Chemistry Score]]>=60,"B-",Table1[[#This Row],[Chemistry Score]]>=50,"C",Table1[[#This Row],[Chemistry Score]]>=40,"D",Table1[[#This Row],[Chemistry Score]]<40,"F")} -> A+ | T3: 90 | U3: {=_xlfn.IFS(Table1[[#This Row],[Biology Score]]>=90,"A+",Table1[[#This Row],[Biology Score]]>=80,"A", Table1[[#This Row],[Biology Score]]>=75,"A-",Table1[[#This Row],[Biology Score]]>=70,"B+",Table1[[#This Row],[Biology Score]]>=65,"B",Table1[[#This Row],[Biology Score]]>=60,"B-",Table1[[#This Row],[Biology Score]]>=50,"C",Table1[[#This Row],[Biology Score]]>=40,"D",Table1[[#This Row],[Biology Score]]<40,"F")} -> A+ | V3: 88 | W3: {=_xlfn.IFS(Table1[[#This Row],[English Score]]>=90,"A+",Table1[[#This Row],[English Score]]>=80,"A", Table1[[#This Row],[English Score]]>=75,"A-",Table1[[#This Row],[English Score]]>=70,"B+",Table1[[#This Row],[English Score]]>=65,"B",Table1[[#This Row],[English Score]]>=60,"B-",Table1[[#This Row],[English Score]]>=50,"C",Table1[[#This Row],[English Score]]>=40,"D",Table1[[#This Row],[English Score]]<40,"F")} -> A | X3: 90 | Y3: {=_xlfn.IFS(Table1[[#This Row],[Geography Score]]>=90,"A+",Table1[[#This Row],[Geography Score]]>=80,"A", Table1[[#This Row],[Geography Score]]>=75,"A-",Table1[[#This Row],[Geography Score]]>=70,"B+",Table1[[#This Row],[Geography Score]]>=65,"B",Table1[[#This Row],[Geography Score]]>=60,"B-",Table1[[#This Row],[Geography Score]]>=50,"C",Table1[[#This Row],[Geography Score]]>=40,"D",Table1[[#This Row],[Geography Score]]<40,"F")} -> A+ | Z3: =SUM(Table1[[#This Row],[Math Score]],Table1[[#This Row],[History Score]],Table1[[#This Row],[Physics Score]],Table1[[#This Row],[Chemistry Score]],Table1[[#This Row],[Biology Score]],Table1[[#This Row],[English Score]],Table1[[#This Row],[Geography Score]]) -> 640 | AA3: =AVERAGE(Table1[[#This Row],[Math Score]],Table1[[#This Row],[History Score]],Table1[[#This Row],[Physics Score]],Table1[[#This Row],[Chemistry Score]],Table1[[#This Row],[Biology Score]],Table1[[#This Row],[English Score]],Table1[[#This Row],[Geography Score]]) -> 91.428571 | AB3: =_xlfn.IFS(Table1[[#This Row],[Average Score]]>=90,"A+",Table1[[#This Row],[Average Score]]>=80,"A", Table1[[#This Row],[Average Score]]>=75,"A-",Table1[[#This Row],[Average Score]]>=70,"B+",Table1[[#This Row],[Average Score]]>=65,"B",Table1[[#This Row],[Average Score]]>=60,"B-",Table1[[#This Row],[Average Score]]>=50,"C",Table1[[#This Row],[Average Score]]>=40,"D",Table1[[#This Row],[Average Score]]<40,"F") -> A+ | AC3: =RANK(AA3,$AA$2:$AA$2001,0) -> 98 | AD3: =_xlfn.IFS(Table1[[#This Row],[Absence Days]]<3,"Excellent",Table1[[#This Row],[Absence Days]]<=6,"Good",Table1[[#This Row],[Absence Days]]>6,"Poor") -> Excellent
A4: 3 | B4: Tina | C4: Andrews | D4: =_xlfn.TEXTJOIN(" ",TRUE,Table1[[#This Row],[First Name]:[Last Name]]) -> Tina Andrews | E4: tina.andrews.3@gslingacademy.com | F4: Female | G4: =PROPER(Table1[[#This Row],[Part Time Job]]) -> False | H4: 9 | I4: =PROPER(Table1[[#This Row],[Extracurricular Activities]]) -> True | J4: 13 | K4: Government Officer | L4: 81 | M4: {=_xlfn.IFS(Table1[[#This Row],[Math Score]]>=90,"A+",Table1[[#This Row],[Math Score]]>=80,"A", Table1[[#This Row],[Math Score]]>=75,"A-",Table1[[#This Row],[Math Score]]>=70,"B+",Table1[[#This Row],[Math Score]]>=65,"B",Table1[[#This Row],[Math Score]]>=60,"B-",Table1[[#This Row],[Math Score]]>=50,"C",Table1[[#This Row],[Math Score]]>=40,"D",Table1[[#This Row],[Math Score]]<40,"F")} -> A | N4: 97 | O4: {=_xlfn.IFS(Table1[[#This Row],[History Score]]>=90,"A+",Table1[[#This Row],[History Score]]>=80,"A", Table1[[#This Row],[History Score]]>=75,"A-",Table1[[#This Row],[History Score]]>=70,"B+",Table1[[#This Row],[History Score]]>=65,"B",Table1[[#This Row],[History Score]]>=60,"B-",Table1[[#This Row],[History Score]]>=50,"C",Table1[[#This Row],[History Score]]>=40,"D",Table1[[#This Row],[History Score]]<40,"F")} -> A+ | P4: 95 | Q4: {=_xlfn.IFS(Table1[[#This Row],[Physics Score]]>=90,"A+",Table1[[#This Row],[Physics Score]]>=80,"A", Table1[[#This Row],[Physics Score]]>=75,"A-",Table1[[#This Row],[Physics Score]]>=70,"B+",Table1[[#This Row],[Physics Score]]>=65,"B",Table1[[#This Row],[Physics Score]]>=60,"B-",Table1[[#This Row],[Physics Score]]>=50,"C",Table1[[#This Row],[Physics Score]]>=40,"D",Table1[[#This Row],[Physics Score]]<40,"F")} -> A+ | R4: 96 | S4: {=_xlfn.IFS(Table1[[#This Row],[Chemistry Score]]>=90,"A+",Table1[[#This Row],[Chemistry Score]]>=80,"A", Table1[[#This Row],[Chemistry Score]]>=75,"A-",Table1[[#This Row],[Chemistry Score]]>=70,"B+",Table1[[#This Row],[Chemistry Score]]>=65,"B",Table1[[#This Row],[Chemistry Score]]>=60,"B-",Table1[[#This Row],[Chemistry Score]]>=50,"C",Table1[[#This Row],[Chemistry Score]]>=40,"D",Table1[[#This Row],[Chemistry Score]]<40,"F")} -> A+ | T4: 65 | U4: {=_xlfn.IFS(Table1[[#This Row],[Biology Score]]>=90,"A+",Table1[[#This Row],[Biology Score]]>=80,"A", Table1[[#This Row],[Biology Score]]>=75,"A-",Table1[[#This Row],[Biology Score]]>=70,"B+",Table1[[#This Row],[Biology Score]]>=65,"B",Table1[[#This Row],[Biology Score]]>=60,"B-",Table1[[#This Row],[Biology Score]]>=50,"C",Table1[[#This Row],[Biology Score]]>=40,"D",Table1[[#This Row],[Biology Score]]<40,"F")} -> B | V4: 77 | W4: {=_xlfn.IFS(Table1[[#This Row],[English Score]]>=90,"A+",Table1[[#This Row],[English Score]]>=80,"A", Table1[[#This Row],[English Score]]>=75,"A-",Table1[[#This Row],[English Score]]>=70,"B+",Table1[[#This Row],[English Score]]>=65,"B",Table1[[#This Row],[English Score]]>=60,"B-",Table1[[#This Row],[English Score]]>=50,"C",Table1[[#This Row],[English Score]]>=40,"D",Table1[[#This Row],[English Score]]<40,"F")} -> A- | X4: 94 | Y4: {=_xlfn.IFS(Table1[[#This Row],[Geography Score]]>=90,"A+",Table1[[#This Row],[Geography Score]]>=80,"A", Table1[[#This Row],[Geography Score]]>=75,"A-",Table1[[#This Row],[Geography Score]]>=70,"B+",Table1[[#This Row],[Geography Score]]>=65,"B",Table1[[#This Row],[Geography Score]]>=60,"B-",Table1[[#This Row],[Geography Score]]>=50,"C",Table1[[#This Row],[Geography Score]]>=40,"D",Table1[[#This Row],[Geography Score]]<40,"F")} -> A+ | Z4: =SUM(Table1[[#This Row],[Math Score]],Table1[[#This Row],[History Score]],Table1[[#This Row],[Physics Score]],Table1[[#This Row],[Chemistry Score]],Table1[[#This Row],[Biology Score]],Table1[[#This Row],[English Score]],Table1[[#This Row],[Geography Score]]) -> 605 | AA4: =AVERAGE(Table1[[#This Row],[Math Score]],Table1[[#This Row],[History Score]],Table1[[#This Row],[Physics Score]],Table1[[#This Row],[Chemistry Score]],Table1[[#This Row],[Biology Score]],Table1[[#This Row],[English Score]],Table1[[#This Row],[Geography Score]]) -> 86.428571 | AB4: =_xlfn.IFS(Table1[[#This Row],[Average Score]]>=90,"A+",Table1[[#This Row],[Average Score]]>=80,"A", Table1[[#This Row],[Average Score]]>=75,"A-",Table1[[#This Row],[Average Score]]>=70,"B+",Table1[[#This Row],[Average Score]]>=65,"B",Table1[[#This Row],[Average Score]]>=60,"B-",Table1[[#This Row],[Average Score]]>=50,"C",Table1[[#This Row],[Average Score]]>=40,"D",Table1[[#This Row],[Average Score]]<40,"F") -> A | AC4: =RANK(AA4,$AA$2:$AA$2001,0) -> 344 | AD4: =_xlfn.IFS(Table1[[#This Row],[Absence Days]]<3,"Excellent",Table1[[#This Row],[Absence Days]]<=6,"Good",Table1[[#This Row],[Absence Days]]>6,"Poor") -> Poor
A5: 4 | B5: Tara | C5: Clark | D5: =_xlfn.TEXTJOIN(" ",TRUE,Table1[[#This Row],[First Name]:[Last Name]]) -> Tara Clark | E5: tara.clark.4@gslingacademy.com | F5: Female | G5: =PROPER(Table1[[#This Row],[Part Time Job]]) -> False | H5: 5 | I5: =PROPER(Table1[[#This Row],[Extracurricular Activities]]) -> False | J5: 3 | K5: Artist | L5: 71 | M5: {=_xlfn.IFS(Table1[[#This Row],[Math Score]]>=90,"A+",Table1[[#This Row],[Math Score]]>=80,"A", Table1[[#This Row],[Math Score]]>=75,"A-",Table1[[#This Row],[Math Score]]>=70,"B+",Table1[[#This Row],[Math Score]]>=65,"B",Table1[[#This Row],[Math Score]]>=60,"B-",Table1[[#This Row],[Math Score]]>=50,"C",Table1[[#This Row],[Math Score]]>=40,"D",Table1[[#This Row],[Math Score]]<40,"F")} -> B+ | N5: 74 | O5: {=_xlfn.IFS(Table1[[#This Row],[History Score]]>=90,"A+",Table1[[#This Row],[History Score]]>=80,"A", Table1[[#This Row],[History Score]]>=75,"A-",Table1[[#This Row],[History Score]]>=70,"B+",Table1[[#This Row],[History Score]]>=65,"B",Table1[[#This Row],[History Score]]>=60,"B-",Table1[[#This Row],[History Score]]>=50,"C",Table1[[#This Row],[History Score]]>=40,"D",Table1[[#This Row],[History Score]]<40,"F")} -> B+ | P5: 88 | Q5: {=_xlfn.IFS(Table1[[#This Row],[Physics Score]]>=90,"A+",Table1[[#This Row],[Physics Score]]>=80,"A", Table1[[#This Row],[Physics Score]]>=75,"A-",Table1[[#This Row],[Physics Score]]>=70,"B+",Table1[[#This Row],[Physics Score]]>=65,"B",Table1[[#This Row],[Physics Score]]>=60,"B-",Table1[[#This Row],[Physics Score]]>=50,"C",Table1[[#This Row],[Physics Score]]>=40,"D",Table1[[#This Row],[Physics Score]]<40,"F")} -> A | R5: 80 | S5: {=_xlfn.IFS(Table1[[#This Row],[Chemistry Score]]>=90,"A+",Table1[[#This Row],[Chemistry Score]]>=80,"A", Table1[[#This Row],[Chemistry Score]]>=75,"A-",Table1[[#This Row],[Chemistry Score]]>=70,"B+",Table1[[#This Row],[Chemistry Score]]>=65,"B",Table1[[#This Row],[Chemistry Score]]>=60,"B-",Table1[[#This Row],[Chemistry Score]]>=50,"C",Table1[[#This Row],[Chemistry Score]]>=40,"D",Table1[[#This Row],[Chemistry Score]]<40,"F")} -> A | T5: 89 | U5: {=_xlfn.IFS(Table1[[#This Row],[Biology Score]]>=90,"A+",Table1[[#This Row],[Biology Score]]>=80,"A", Table1[[#This Row],[Biology Score]]>=75,"A-",Table1[[#This Row],[Biology Score]]>=70,"B+",Table1[[#This Row],[Biology Score]]>=65,"B",Table1[[#This Row],[Biology Score]]>=60,"B-",Table1[[#This Row],[Biology Score]]>=50,"C",Table1[[#This Row],[Biology Score]]>=40,"D",Table1[[#This Row],[Biology Score]]<40,"F")} -> A | V5: 63 | W5: {=_xlfn.IFS(Table1[[#This Row],[English Score]]>=90,"A+",Table1[[#This Row],[English Score]]>=80,"A", Table1[[#This Row],[English Score]]>=75,"A-",Table1[[#This Row],[English Score]]>=70,"B+",Table1[[#This Row],[English Score]]>=65,"B",Table1[[#This Row],[English Score]]>=60,"B-",Table1[[#This Row],[English Score]]>=50,"C",Table1[[#This Row],[English Score]]>=40,"D",Table1[[#This Row],[English Score]]<40,"F")} -> B- | X5: 86 | Y5: {=_xlfn.IFS(Table1[[#This Row],[Geography Score]]>=90,"A+",Table1[[#This Row],[Geography Score]]>=80,"A", Table1[[#This Row],[Geography Score]]>=75,"A-",Table1[[#This Row],[Geography Score]]>=70,"B+",Table1[[#This Row],[Geography Score]]>=65,"B",Table1[[#This Row],[Geography Score]]>=60,"B-",Table1[[#This Row],[Geography Score]]>=50,"C",Table1[[#This Row],[Geography Score]]>=40,"D",Table1[[#This Row],[Geography Score]]<40,"F")} -> A | Z5: =SUM(Table1[[#This Row],[Math Score]],Table1[[#This Row],[History Score]],Table1[[#This Row],[Physics Score]],Table1[[#This Row],[Chemistry Score]],Table1[[#This Row],[Biology Score]],Table1[[#This Row],[English Score]],Table1[[#This Row],[Geography Score]]) -> 551 | AA5: =AVERAGE(Table1[[#This Row],[Math Score]],Table1[[#This Row],[History Score]],Table1[[#This Row],[Physics Score]],Table1[[#This Row],[Chemistry Score]],Table1[[#This Row],[Biology Score]],Table1[[#This Row],[English Score]],Table1[[#This Row],[Geography Score]]) -> 78.714286 | AB5: =_xlfn.IFS(Table1[[#This Row],[Average Score]]>=90,"A+",Table1[[#This Row],[Average Score]]>=80,"A", Table1[[#This Row],[Average Score]]>=75,"A-",Table1[[#This Row],[Average Score]]>=70,"B+",Table1[[#This Row],[Average Score]]>=65,"B",Table1[[#This Row],[Average Score]]>=60,"B-",Table1[[#This Row],[Average Score]]>=50,"C",Table1[[#This Row],[Average Score]]>=40,"D",Table1[[#This Row],[Average Score]]<40,"F") -> A- | AC5: =RANK(AA5,$AA$2:$AA$2001,0) -> 1317 | AD5: =_xlfn.IFS(Table1[[#This Row],[Absence Days]]<3,"Excellent",Table1[[#This Row],[Absence Days]]<=6,"Good",Table1[[#This Row],[Absence Days]]>6,"Poor") -> Good
A6: 5 | B6: Anthony | C6: Campos | D6: =_xlfn.TEXTJOIN(" ",TRUE,Table1[[#This Row],[First Name]:[Last Name]]) -> Anthony Campos | E6: anthony.campos.5@gslingacademy.com | F6: Male | G6: =PROPER(Table1[[#This Row],[Part Time Job]]) -> False | H6: 5 | I6: =PROPER(Table1[[#This Row],[Extracurricular Activities]]) -> False | J6: 10 | K6: Unknown | L6: 84 | M6: {=_xlfn.IFS(Table1[[#This Row],[Math Score]]>=90,"A+",Table1[[#This Row],[Math Score]]>=80,"A", Table1[[#This Row],[Math Score]]>=75,"A-",Table1[[#This Row],[Math Score]]>=70,"B+",Table1[[#This Row],[Math Score]]>=65,"B",Table1[[#This Row],[Math Score]]>=60,"B-",Table1[[#This Row],[Math Score]]>=50,"C",Table1[[#This Row],[Math Score]]>=40,"D",Table1[[#This Row],[Math Score]]<40,"F")} -> A | N6: 77 | O6: {=_xlfn.IFS(Table1[[#This Row],[History Score]]>=90,"A+",Table1[[#This Row],[History Score]]>=80,"A", Table1[[#This Row],[History Score]]>=75,"A-",Table1[[#This Row],[History Score]]>=70,"B+",Table1[[#This Row],[History Score]]>=65,"B",Table1[[#This Row],[History Score]]>=60,"B-",Table1[[#This Row],[History Score]]>=50,"C",Table1[[#This Row],[History Score]]>=40,"D",Table1[[#This Row],[History Score]]<40,"F")} -> A- | P6: 65 | Q6: {=_xlfn.IFS(Table1[[#This Row],[Physics Score]]>=90,"A+",Table1[[#This Row],[Physics Score]]>=80,"A", Table1[[#This Row],[Physics Score]]>=75,"A-",Table1[[#This Row],[Physics Score]]>=70,"B+",Table1[[#This Row],[Physics Score]]>=65,"B",Table1[[#This Row],[Physics Score]]>=60,"B-",Table1[[#This Row],[Physics Score]]>=50,"C",Table1[[#This Row],[Physics Score]]>=40,"D",Table1[[#This Row],[Physics Score]]<40,"F")} -> B | R6: 65 | S6: {=_xlfn.IFS(Table1[[#This Row],[Chemistry Score]]>=90,"A+",Table1[[#This Row],[Chemistry Score]]>=80,"A", Table1[[#This Row],[Chemistry Score]]>=75,"A-",Table1[[#This Row],[Chemistry Score]]>=70,"B+",Table1[[#This Row],[Chemistry Score]]>=65,"B",Table1[[#This Row],[Chemistry Score]]>=60,"B-",Table1[[#This Row],[Chemistry Score]]>=50,"C",Table1[[#This Row],[Chemistry Score]]>=40,"D",Table1[[#This Row],[Chemistry Score]]<40,"F")} -> B | T6: 80 | U6: {=_xlfn.IFS(Table1[[#This Row],[Biology Score]]>=90,"A+",Table1[[#This Row],[Biology Score]]>=80,"A", Table1[[#This Row],[Biology Score]]>=75,"A-",Table1[[#This Row],[Biology Score]]>=70,"B+",Table1[[#This Row],[Biology Score]]>=65,"B",Table1[[#This Row],[Biology Score]]>=60,"B-",Table1[[#This Row],[Biology Score]]>=50,"C",Table1[[#This Row],[Biology Score]]>=40,"D",Table1[[#This Row],[Biology Score]]<40,"F")} -> A | V6: 74 | W6: {=_xlfn.IFS(Table1[[#This Row],[English Score]]>=90,"A+",Table1[[#This Row],[English Score]]>=80,"A", Table1[[#This Row],[English Score]]>=75,"A-",Table1[[#This Row],[English Score]]>=70,"B+",Table1[[#This Row],[English Score]]>=65,"B",Table1[[#This Row],[English Score]]>=60,"B-",Table1[[#This Row],[English Score]]>=50,"C",Table1[[#This Row],[English Score]]>=40,"D",Table1[[#This Row],[English Score]]<40,"F")} -> B+ | X6: 76 | Y6: {=_xlfn.IFS(Table1[[#This Row],[Geography Score]]>=90,"A+",Table1[[#This Row],[Geography Score]]>=80,"A", Table1[[#This Row],[Geography Score]]>=75,"A-",Table1[[#This Row],[Geography Score]]>=70,"B+",Table1[[#This Row],[Geography Score]]>=65,"B",Table1[[#This Row],[Geography Score]]>=60,"B-",Table1[[#This Row],[Geography Score]]>=50,"C",Table1[[#This Row],[Geography Score]]>=40,"D",Table1[[#This Row],[Geography Score]]<40,"F")} -> A- | Z6: =SUM(Table1[[#This Row],[Math Score]],Table1[[#This Row],[History Score]],Table1[[#This Row],[Physics Score]],Table1[[#This Row],[Chemistry Score]],Table1[[#This Row],[Biology Score]],Table1[[#This Row],[English Score]],Table1[[#This Row],[Geography Score]]) -> 521 | AA6: =AVERAGE(Table1[[#This Row],[Math Score]],Table1[[#This Row],[History Score]],Table1[[#This Row],[Physics Score]],Table1[[#This Row],[Chemistry Score]],Table1[[#This Row],[Biology Score]],Table1[[#This Row],[English Score]],Table1[[#This Row],[Geography Score]]) -> 74.428571 | AB6: =_xlfn.IFS(Table1[[#This Row],[Average Score]]>=90,"A+",Table1[[#This Row],[Average Score]]>=80,"A", Table1[[#This Row],[Average Score]]>=75,"A-",Table1[[#This Row],[Average Score]]>=70,"B+",Table1[[#This Row],[Average Score]]>=65,"B",Table1[[#This Row],[Average Score]]>=60,"B-",Table1[[#This Row],[Average Score]]>=50,"C",Table1[[#This Row],[Average Score]]>=40,"D",Table1[[#This Row],[Average Score]]<40,"F") -> B+ | AC6: =RANK(AA6,$AA$2:$AA$2001,0) -> 1749 | AD6: =_xlfn.IFS(Table1[[#This Row],[Absence Days]]<3,"Excellent",Table1[[#This Row],[Absence Days]]<=6,"Good",Table1[[#This Row],[Absence Days]]>6,"Poor") -> Good
A7: 6 | B7: Kelly | C7: Wade | D7: =_xlfn.TEXTJOIN(" ",TRUE,Table1[[#This Row],[First Name]:[Last Name]]) -> Kelly Wade | E7: kelly.wade.6@gslingacademy.com | F7: Female | G7: =PROPER(Table1[[#This Row],[Part Time Job]]) -> False | H7: 2 | I7: =PROPER(Table1[[#This Row],[Extracurricular Activities]]) -> False | J7: 26 | K7: Unknown | L7: 93 | M7: {=_xlfn.IFS(Table1[[#This Row],[Math Score]]>=90,"A+",Table1[[#This Row],[Math Score]]>=80,"A", Table1[[#This Row],[Math Score]]>=75,"A-",Table1[[#This Row],[Math Score]]>=70,"B+",Table1[[#This Row],[Math Score]]>=65,"B",Table1[[#This Row],[Math Score]]>=60,"B-",Table1[[#This Row],[Math Score]]>=50,"C",Table1[[#This Row],[Math Score]]>=40,"D",Table1[[#This Row],[Math Score]]<40,"F")} -> A+ | N7: 100 | O7: {=_xlfn.IFS(Table1[[#This Row],[History Score]]>=90,"A+",Table1[[#This Row],[History Score]]>=80,"A", Table1[[#This Row],[History Score]]>=75,"A-",Table1[[#This Row],[History Score]]>=70,"B+",Table1[[#This Row],[History Score]]>=65,"B",Table1[[#This Row],[History Score]]>=60,"B-",Table1[[#This Row],[History Score]]>=50,"C",Table1[[#This Row],[History Score]]>=40,"D",Table1[[#This Row],[History Score]]<40,"F")} -> A+ | P7: 67 | Q7: {=_xlfn.IFS(Table1[[#This Row],[Physics Score]]>=90,"A+",Table1[[#This Row],[Physics Score]]>=80,"A", Table1[[#This Row],[Physics Score]]>=75,"A-",Table1[[#This Row],[Physics Score]]>=70,"B+",Table1[[#This Row],[Physics Score]]>=65,"B",Table1[[#This Row],[Physics Score]]>=60,"B-",Table1[[#This Row],[Physics Score]]>=50,"C",Table1[[#This Row],[Physics Score]]>=40,"D",Table1[[#This Row],[Physics Score]]<40,"F")} -> B | R7: 78 | S7: {=_xlfn.IFS(Table1[[#This Row],[Chemistry Score]]>=90,"A+",Table1[[#This Row],[Chemistry Score]]>=80,"A", Table1[[#This Row],[Chemistry Score]]>=75,"A-",Table1[[#This Row],[Chemistry Score]]>=70,"B+",Table1[[#This Row],[Chemistry Score]]>=65,"B",Table1[[#This Row],[Chemistry Score]]>=60,"B-",Table1[[#This Row],[Chemistry Score]]>=50,"C",Table1[[#This Row],[Chemistry Score]]>=40,"D",Table1[[#This Row],[Chemistry Score]]<40,"F")} -> A- | T7: 72 | U7: {=_xlfn.IFS(Table1[[#This Row],[Biology Score]]>=90,"A+",Table1[[#This Row],[Biology Score]]>=80,"A", Table1[[#This Row],[Biology Score]]>=75,"A-",Table1[[#This Row],[Biology Score]]>=70,"B+",Table1[[#This Row],[Biology Score]]>=65,"B",Table1[[#This Row],[Biology Score]]>=60,"B-",Table1[[#This Row],[Biology Score]]>=50,"C",Table1[[#This Row],[Biology Score]]>=40,"D",Table1[[#This Row],[Biology Score]]<40,"F")} -> B+ | V7: 80 | W7: {=_xlfn.IFS(Table1[[#This Row],[English Score]]>=90,"A+",Table1[[#This Row],[English Score]]>=80,"A", Table1[[#This Row],[English Score]]>=75,"A-",Table1[[#This Row],[English Score]]>=70,"B+",Table1[[#This Row],[English Score]]>=65,"B",Table1[[#This Row],[English Score]]>=60,"B-",Table1[[#This Row],[English Score]]>=50,"C",Table1[[#This Row],[English Score]]>=40,"D",Table1[[#This Row],[English Score]]<40,"F")} -> A | X7: 84 | Y7: {=_xlfn.IFS(Table1[[#This Row],[Geography Score]]>=90,"A+",Table1[[#This Row],[Geography Score]]>=80,"A", Table1[[#This Row],[Geography Score]]>=75,"A-",Table1[[#This Row],[Geography Score]]>=70,"B+",Table1[[#This Row],[Geography Score]]>=65,"B",Table1[[#This Row],[Geography Score]]>=60,"B-",Table1[[#This Row],[Geography Score]]>=50,"C",Table1[[#This Row],[Geography Score]]>=40,"D",Table1[[#This Row],[Geography Score]]<40,"F")} -> A | Z7: =SUM(Table1[[#This Row],[Math Score]],Table1[[#This Row],[History Score]],Table1[[#This Row],[Physics Score]],Table1[[#This Row],[Chemistry Score]],Table1[[#This Row],[Biology Score]],Table1[[#This Row],[English Score]],Table1[[#This Row],[Geography Score]]) -> 574 | AA7: =AVERAGE(Table1[[#This Row],[Math Score]],Table1[[#This Row],[History Score]],Table1[[#This Row],[Physics Score]],Table1[[#This Row],[Chemistry Score]],Table1[[#This Row],[Biology Score]],Table1[[#This Row],[English Score]],Table1[[#This Row],[Geography Score]]) -> 82 | AB7: =_xlfn.IFS(Table1[[#This Row],[Average Score]]>=90,"A+",Table1[[#This Row],[Average Score]]>=80,"A", Table1[[#This Row],[Average Score]]>=75,"A-",Table1[[#This Row],[Average Score]]>=70,"B+",Table1[[#This Row],[Average Score]]>=65,"B",Table1[[#This Row],[Average Score]]>=60,"B-",Table1[[#This Row],[Average Score]]>=50,"C",Table1[[#This Row],[Average Score]]>=40,"D",Table1[[#This Row],[Average Score]]<40,"F") -> A | AC7: =RANK(AA7,$AA$2:$AA$2001,0) -> 832 | AD7: =_xlfn.IFS(Table1[[#This Row],[Absence Days]]<3,"Excellent",Table1[[#This Row],[Absence Days]]<=6,"Good",Table1[[#This Row],[Absence Days]]>6,"Poor") -> Excellent
A8: 7 | B8: Anthony | C8: Smith | D8: =_xlfn.TEXTJOIN(" ",TRUE,Table1[[#This Row],[First Name]:[Last Name]]) -> Anthony Smith | E8: anthony.smith.7@gslingacademy.com | F8: Male | G8: =PROPER(Table1[[#This Row],[Part Time Job]]) -> False | H8: 3 | I8: =PROPER(Table1[[#This Row],[Extracurricular Activities]]) -> True | J8: 23 | K8: Software Engineer | L8: 99 | M8: {=_xlfn.IFS(Table1[[#This Row],[Math Score]]>=90,"A+",Table1[[#This Row],[Math Score]]>=80,"A", Table1[[#This Row],[Math Score]]>=75,"A-",Table1[[#This Row],[Math Score]]>=70,"B+",Table1[[#This Row],[Math Score]]>=65,"B",Table1[[#This Row],[Math Score]]>=60,"B-",Table1[[#This Row],[Math Score]]>=50,"C",Table1[[#This Row],[Math Score]]>=40,"D",Table1[[#This Row],[Math Score]]<40,"F")} -> A+ | N8: 96 | O8: {=_xlfn.IFS(Table1[[#This Row],[History Score]]>=90,"A+",Table1[[#This Row],[History Score]]>=80,"A", Table1[[#This Row],[History Score]]>=75,"A-",Table1[[#This Row],[History Score]]>=70,"B+",Table1[[#This Row],[History Score]]>=65,"B",Table1[[#This Row],[History Score]]>=60,"B-",Table1[[#This Row],[History Score]]>=50,"C",Table1[[#This Row],[History Score]]>=40,"D",Table1[[#This Row],[History Score]]<40,"F")} -> A+ | P8: 97 | Q8: {=_xlfn.IFS(Table1[[#This Row],[Physics Score]]>=90,"A+",Table1[[#This Row],[Physics Score]]>=80,"A", Table1[[#This Row],[Physics Score]]>=75,"A-",Table1[[#This Row],[Physics Score]]>=70,"B+",Table1[[#This Row],[Physics Score]]>=65,"B",Table1[[#This Row],[Physics Score]]>=60,"B-",Table1[[#This Row],[Physics Score]]>=50,"C",Table1[[#This Row],[Physics Score]]>=40,"D",Table1[[#This Row],[Physics Score]]<40,"F")} -> A+ | R8: 73 | S8: {=_xlfn.IFS(Table1[[#This Row],[Chemistry Score]]>=90,"A+",Table1[[#This Row],[Chemistry Score]]>=80,"A", Table1[[#This Row],[Chemistry Score]]>=75,"A-",Table1[[#This Row],[Chemistry Score]]>=70,"B+",Table1[[#This Row],[Chemistry Score]]>=65,"B",Table1[[#This Row],[Chemistry Score]]>=60,"B-",Table1[[#This Row],[Chemistry Score]]>=50,"C",Table1[[#This Row],[Chemistry Score]]>=40,"D",Table1[[#This Row],[Chemistry Score]]<40,"F")} -> B+ | T8: 88 | U8: {=_xlfn.IFS(Table1[[#This Row],[Biology Score]]>=90,"A+",Table1[[#This Row],[Biology Score]]>=80,"A", Table1[[#This Row],[Biology Score]]>=75,"A-",Table1[[#This Row],[Biology Score]]>=70,"B+",Table1[[#This Row],[Biology Score]]>=65,"B",Table1[[#This Row],[Biology Score]]>=60,"B-",Table1[[#This Row],[Biology Score]]>=50,"C",Table1[[#This Row],[Biology Score]]>=40,"D",Table1[[#This Row],[Biology Score]]<40,"F")} -> A | V8: 76 | W8: {=_xlfn.IFS(Table1[[#This Row],[English Score]]>=90,"A+",Table1[[#This Row],[English Score]]>=80,"A", Table1[[#This Row],[English Score]]>=75,"A-",Table1[[#This Row],[English Score]]>=70,"B+",Table1[[#This Row],[English Score]]>=65,"B",Table1[[#This Row],[English Score]]>=60,"B-",Table1[[#This Row],[English Score]]>=50,"C",Table1[[#This Row],[English Score]]>=40,"D",Table1[[#This Row],[English Score]]<40,"F")} -> A- | X8: 64 | Y8: {=_xlfn.IFS(Table1[[#This Row],[Geography Score]]>=90,"A+",Table1[[#This Row],[Geography Score]]>=80,"A", Table1[[#This Row],[Geography Score]]>=75,"A-",Table1[[#This Row],[Geography Score]]>=70,"B+",Table1[[#This Row],[Geography Score]]>=65,"B",Table1[[#This Row],[Geography Score]]>=60,"B-",Table1[[#This Row],[Geography Score]]>=50,"C",Table1[[#This Row],[Geography Score]]>=40,"D",Table1[[#This Row],[Geography Score]]<40,"F")} -> B- | Z8: =SUM(Table1[[#This Row],[Math Score]],Table1[[#This Row],[History Score]],Table1[[#This Row],[Physics Score]],Table1[[#This Row],[Chemistry Score]],Table1[[#This Row],[Biology Score]],Table1[[#This Row],[English Score]],Table1[[#This Row],[Geography Score]]) -> 593 | AA8: =AVERAGE(Table1[[#This Row],[Math Score]],Table1[[#This Row],[History Score]],Table1[[#This Row],[Physics Score]],Table1[[#This Row],[Chemistry Score]],Table1[[#This Row],[Biology Score]],Table1[[#This Row],[English Score]],Table1[[#This Row],[Geography Score]]) -> 84.714286 | AB8: =_xlfn.IFS(Table1[[#This Row],[Average Score]]>=90,"A+",Table1[[#This Row],[Average Score]]>=80,"A", Table1[[#This Row],[Average Score]]>=75,"A-",Table1[[#This Row],[Average Score]]>=70,"B+",Table1[[#This Row],[Average Score]]>=65,"B",Table1[[#This Row],[Average Score]]>=60,"B-",Table1[[#This Row],[Average Score]]>=50,"C",Table1[[#This Row],[Average Score]]>=40,"D",Table1[[#This Row],[Average Score]]<40,"F") -> A | AC8: =RANK(AA8,$AA$2:$AA$2001,0) -> 494 | AD8: =_xlfn.IFS(Table1[[#This Row],[Absence Days]]<3,"Excellent",Table1[[#This Row],[Absence Days]]<=6,"Good",Table1[[#This Row],[Absence Days]]>6,"Poor") -> Good
A9: 8 | B9: George | C9: Short | D9: =_xlfn.TEXTJOIN(" ",TRUE,Table1[[#This Row],[First Name]:[Last Name]]) -> George Short | E9: george.short.8@gslingacademy.com | F9: Male | G9: =PROPER(Table1[[#This Row],[Part Time Job]]) -> True | H9: 2 | I9: =PROPER(Table1[[#This Row],[Extracurricular Activities]]) -> True | J9: 34 | K9: Software Engineer | L9: 95 | M9: {=_xlfn.IFS(Table1[[#This Row],[Math Score]]>=90,"A+",Table1[[#This Row],[Math Score]]>=80,"A", Table1[[#This Row],[Math Score]]>=75,"A-",Table1[[#This Row],[Math Score]]>=70,"B+",Table1[[#This Row],[Math Score]]>=65,"B",Table1[[#This Row],[Math Score]]>=60,"B-",Table1[[#This Row],[Math Score]]>=50,"C",Table1[[#This Row],[Math Score]]>=40,"D",Table1[[#This Row],[Math Score]]<40,"F")} -> A+ | N9: 95 | O9: {=_xlfn.IFS(Table1[[#This Row],[History Score]]>=90,"A+",Table1[[#This Row],[History Score]]>=80,"A", Table1[[#This Row],[History Score]]>=75,"A-",Table1[[#This Row],[History Score]]>=70,"B+",Table1[[#This Row],[History Score]]>=65,"B",Table1[[#This Row],[History Score]]>=60,"B-",Table1[[#This Row],[History Score]]>=50,"C",Table1[[#This Row],[History Score]]>=40,"D",Table1[[#This Row],[History Score]]<40,"F")} -> A+ | P9: 82 | Q9: {=_xlfn.IFS(Table1[[#This Row],[Physics Score]]>=90,"A+",Table1[[#This Row],[Physics Score]]>=80,"A", Table1[[#This Row],[Physics Score]]>=75,"A-",Table1[[#This Row],[Physics Score]]>=70,"B+",Table1[[#This Row],[Physics Score]]>=65,"B",Table1[[#This Row],[Physics Score]]>=60,"B-",Table1[[#This Row],[Physics Score]]>=50,"C",Table1[[#This Row],[Physics Score]]>=40,"D",Table1[[#This Row],[Physics Score]]<40,"F")} -> A | R9: 63 | S9: {=_xlfn.IFS(Table1[[#This Row],[Chemistry Score]]>=90,"A+",Table1[[#This Row],[Chemistry Score]]>=80,"A", Table1[[#This Row],[Chemistry Score]]>=75,"A-",Table1[[#This Row],[Chemistry Score]]>=70,"B+",Table1[[#This Row],[Chemistry Score]]>=65,"B",Table1[[#This Row],[Chemistry Score]]>=60,"B-",Table1[[#This Row],[Chemistry Score]]>=50,"C",Table1[[#This Row],[Chemistry Score]]>=40,"D",Table1[[#This Row],[Chemistry Score]]<40,"F")} -> B- | T9: 84 | U9: {=_xlfn.IFS(Table1[[#This Row],[Biology Score]]>=90,"A+",Table1[[#This Row],[Biology Score]]>=80,"A", Table1[[#This Row],[Biology Score]]>=75,"A-",Table1[[#This Row],[Biology Score]]>=70,"B+",Table1[[#This Row],[Biology Score]]>=65,"B",Table1[[#This Row],[Biology Score]]>=60,"B-",Table1[[#This Row],[Biology Score]]>=50,"C",Table1[[#This Row],[Biology Score]]>=40,"D",Table1[[#This Row],[Biology Score]]<40,"F")} -> A | V9: 70 | W9: {=_xlfn.IFS(Table1[[#This Row],[English Score]]>=90,"A+",Table1[[#This Row],[English Score]]>=80,"A", Table1[[#This Row],[English Score]]>=75,"A-",Table1[[#This Row],[English Score]]>=70,"B+",Table1[[#This Row],[English Score]]>=65,"B",Table1[[#This Row],[English Score]]>=60,"B-",Table1[[#This Row],[English Score]]>=50,"C",Table1[[#This Row],[English Score]]>=40,"D",Table1[[#This Row],[English Score]]<40,"F")} -> B+ | X9: 85 | Y9: {=_xlfn.IFS(Table1[[#This Row],[Geography Score]]>=90,"A+",Table1[[#This Row],[Geography Score]]>=80,"A", Table1[[#This Row],[Geography Score]]>=75,"A-",Table1[[#This Row],[Geography Score]]>=70,"B+",Table1[[#This Row],[Geography Score]]>=65,"B",Table1[[#This Row],[Geography Score]]>=60,"B-",Table1[[#This Row],[Geography Score]]>=50,"C",Table1[[#This Row],[Geography Score]]>=40,"D",Table1[[#This Row],[Geography Score]]<40,"F")} -> A | Z9: =SUM(Table1[[#This Row],[Math Score]],Table1[[#This Row],[History Score]],Table1[[#This Row],[Physics Score]],Table1[[#This Row],[Chemistry Score]],Table1[[#This Row],[Biology Score]],Table1[[#This Row],[English Score]],Table1[[#This Row],[Geography Score]]) -> 574 | AA9: =AVERAGE(Table1[[#This Row],[Math Score]],Table1[[#This Row],[History Score]],Table1[[#This Row],[Physics Score]],Table1[[#This Row],[Chemistry Score]],Table1[[#This Row],[Biology Score]],Table1[[#This Row],[English Score]],Table1[[#This Row],[Geography Score]]) -> 82 | AB9: =_xlfn.IFS(Table1[[#This Row],[Average Score]]>=90,"A+",Table1[[#This Row],[Average Score]]>=80,"A", Table1[[#This Row],[Average Score]]>=75,"A-",Table1[[#This Row],[Average Score]]>=70,"B+",Table1[[#This Row],[Average Score]]>=65,"B",Table1[[#This Row],[Average Score]]>=60,"B-",Table1[[#This Row],[Average Score]]>=50,"C",Table1[[#This Row],[Average Score]]>=40,"D",Table1[[#This Row],[Average Score]]<40,"F") -> A | AC9: =RANK(AA9,$AA$2:$AA$2001,0) -> 832 | AD9: =_xlfn.IFS(Table1[[#This Row],[Absence Days]]<3,"Excellent",Table1[[#This Row],[Absence Days]]<=6,"Good",Table1[[#This Row],[Absence Days]]>6,"Poor") -> Excellent
A10: 9 | B10: Stanley | C10: Gutierrez | D10: =_xlfn.TEXTJOIN(" ",TRUE,Table1[[#This Row],[First Name]:[Last Name]]) -> Stanley Gutierrez | E10: stanley.gutierrez.9@gslingacademy.com | F10: Male | G10: =PROPER(Table1[[#This Row],[Part Time Job]]) -> False | H10: 6 | I10: =PROPER(Table1[[#This Row],[Extracurricular Activities]]) -> False | J10: 25 | K10: Unknown | L10: 94 | M10: {=_xlfn.IFS(Table1[[#This Row],[Math Score]]>=90,"A+",Table1[[#This Row],[Math Score]]>=80,"A", Table1[[#This Row],[Math Score]]>=75,"A-",Table1[[#This Row],[Math Score]]>=70,"B+",Table1[[#This Row],[Math Score]]>=65,"B",Table1[[#This Row],[Math Score]]>=60,"B-",Table1[[#This Row],[Math Score]]>=50,"C",Table1[[#This Row],[Math Score]]>=40,"D",Table1[[#This Row],[Math Score]]<40,"F")} -> A+ | N10: 68 | O10: {=_xlfn.IFS(Table1[[#This Row],[History Score]]>=90,"A+",Table1[[#This Row],[History Score]]>=80,"A", Table1[[#This Row],[History Score]]>=75,"A-",Table1[[#This Row],[History Score]]>=70,"B+",Table1[[#This Row],[History Score]]>=65,"B",Table1[[#This Row],[History Score]]>=60,"B-",Table1[[#This Row],[History Score]]>=50,"C",Table1[[#This Row],[History Score]]>=40,"D",Table1[[#This Row],[History Score]]<40,"F")} -> B | P10: 94 | Q10: {=_xlfn.IFS(Table1[[#This Row],[Physics Score]]>=90,"A+",Table1[[#This Row],[Physics Score]]>=80,"A", Table1[[#This Row],[Physics Score]]>=75,"A-",Table1[[#This Row],[Physics Score]]>=70,"B+",Table1[[#This Row],[Physics Score]]>=65,"B",Table1[[#This Row],[Physics Score]]>=60,"B-",Table1[[#This Row],[Physics Score]]>=50,"C",Table1[[#This Row],[Physics Score]]>=40,"D",Table1[[#This Row],[Physics Score]]<40,"F")} -> A+ | R10: 85 | S10: {=_xlfn.IFS(Table1[[#This Row],[Chemistry Score]]>=90,"A+",Table1[[#This Row],[Chemistry Score]]>=80,"A", Table1[[#This Row],[Chemistry Score]]>=75,"A-",Table1[[#This Row],[Chemistry Score]]>=70,"B+",Table1[[#This Row],[Chemistry Score]]>=65,"B",Table1[[#This Row],[Chemistry Score]]>=60,"B-",Table1[[#This Row],[Chemistry Score]]>=50,"C",Table1[[#This Row],[Chemistry Score]]>=40,"D",Table1[[#This Row],[Chemistry Score]]<40,"F")} -> A | T10: 81 | U10: {=_xlfn.IFS(Table1[[#This Row],[Biology Score]]>=90,"A+",Table1[[#This Row],[Biology Score]]>=80,"A", Table1[[#This Row],[Biology Score]]>=75,"A-",Table1[[#This Row],[Biology Score]]>=70,"B+",Table1[[#This Row],[Biology Score]]>=65,"B",Table1[[#This Row],[Biology Score]]>=60,"B-",Table1[[#This Row],[Biology Score]]>=50,"C",Table1[[#This Row],[Biology Score]]>=40,"D",Table1[[#This Row],[Biology Score]]<40,"F")} -> A | V10: 74 | W10: {=_xlfn.IFS(Table1[[#This Row],[English Score]]>=90,"A+",Table1[[#This Row],[English Score]]>=80,"A", Table1[[#This Row],[English Score]]>=75,"A-",Table1[[#This Row],[English Score]]>=70,"B+",Table1[[#This Row],[English Score]]>=65,"B",Table1[[#This Row],[English Score]]>=60,"B-",Table1[[#This Row],[English Score]]>=50,"C",Table1[[#This Row],[English Score]]>=40,"D",Table1[[#This Row],[English Score]]<40,"F")} -> B+ | X10: 72 | Y10: {=_xlfn.IFS(Table1[[#This Row],[Geography Score]]>=90,"A+",Table1[[#This Row],[Geography Score]]>=80,"A", Table1[[#This Row],[Geography Score]]>=75,"A-",Table1[[#This Row],[Geography Score]]>=70,"B+",Table1[[#This Row],[Geography Score]]>=65,"B",Table1[[#This Row],[Geography Score]]>=60,"B-",Table1[[#This Row],[Geography Score]]>=50,"C",Table1[[#This Row],[Geography Score]]>=40,"D",Table1[[#This Row],[Geography Score]]<40,"F")} -> B+ | Z10: =SUM(Table1[[#This Row],[Math Score]],Table1[[#This Row],[History Score]],Table1[[#This Row],[Physics Score]],Table1[[#This Row],[Chemistry Score]],Table1[[#This Row],[Biology Score]],Table1[[#This Row],[English Score]],Table1[[#This Row],[Geography Score]]) -> 568 | AA10: =AVERAGE(Table1[[#This Row],[Math Score]],Table1[[#This Row],[History Score]],Table1[[#This Row],[Physics Score]],Table1[[#This Row],[Chemistry Score]],Table1[[#This Row],[Biology Score]],Table1[[#This Row],[English Score]],Table1[[#This Row],[Geography Score]]) -> 81.142857 | AB10: =_xlfn.IFS(Table1[[#This Row],[Average Score]]>=90,"A+",Table1[[#This Row],[Average Score]]>=80,"A", Table1[[#This Row],[Average Score]]>=75,"A-",Table1[[#This Row],[Average Score]]>=70,"B+",Table1[[#This Row],[Average Score]]>=65,"B",Table1[[#This Row],[Average Score]]>=60,"B-",Table1[[#This Row],[Average Score]]>=50,"C",Table1[[#This Row],[Average Score]]>=40,"D",Table1[[#This Row],[Average Score]]<40,"F") -> A | AC10: =RANK(AA10,$AA$2:$AA$2001,0) -> 975 | AD10: =_xlfn.IFS(Table1[[#This Row],[Absence Days]]<3,"Excellent",Table1[[#This Row],[Absence Days]]<=6,"Good",Table1[[#This Row],[Absence Days]]>6,"Poor") -> Good
A11: 10 | B11: Audrey | C11: Simpson | D11: =_xlfn.TEXTJOIN(" ",TRUE,Table1[[#This Row],[First Name]:[Last Name]]) -> Audrey Simpson | E11: audrey.simpson.10@gslingacademy.com | F11: Female | G11: =PROPER(Table1[[#This Row],[Part Time Job]]) -> False | H11: 3 | I11: =PROPER(Table1[[#This Row],[Extracurricular Activities]]) -> True | J11: 18 | K11: Teacher | L11: 98 | M11: {=_xlfn.IFS(Table1[[#This Row],[Math Score]]>=90,"A+",Table1[[#This Row],[Math Score]]>=80,"A", Table1[[#This Row],[Math Score]]>=75,"A-",Table1[[#This Row],[Math Score]]>=70,"B+",Table1[[#This Row],[Math Score]]>=65,"B",Table1[[#This Row],[Math Score]]>=60,"B-",Table1[[#This Row],[Math Score]]>=50,"C",Table1[[#This Row],[Math Score]]>=40,"D",Table1[[#This Row],[Math Score]]<40,"F")} -> A+ | N11: 69 | O11: {=_xlfn.IFS(Table1[[#This Row],[History Score]]>=90,"A+",Table1[[#This Row],[History Score]]>=80,"A", Table1[[#This Row],[History Score]]>=75,"A-",Table1[[#This Row],[History Score]]>=70,"B+",Table1[[#This Row],[History Score]]>=65,"B",Table1[[#This Row],[History Score]]>=60,"B-",Table1[[#This Row],[History Score]]>=50,"C",Table1[[#This Row],[History Score]]>=40,"D",Table1[[#This Row],[History Score]]<40,"F")} -> B | P11: 88 | Q11: {=_xlfn.IFS(Table1[[#This Row],[Physics Score]]>=90,"A+",Table1[[#This Row],[Physics Score]]>=80,"A", Table1[[#This Row],[Physics Score]]>=75,"A-",Table1[[#This Row],[Physics Score]]>=70,"B+",Table1[[#This Row],[Physics Score]]>=65,"B",Table1[[#This Row],[Physics Score]]>=60,"B-",Table1[[#This Row],[Physics Score]]>=50,"C",Table1[[#This Row],[Physics Score]]>=40,"D",Table1[[#This Row],[Physics Score]]<40,"F")} -> A | R11: 71 | S11: {=_xlfn.IFS(Table1[[#This Row],[Chemistry Score]]>=90,"A+",Table1[[#This Row],[Chemistry Score]]>=80,"A", Table1[[#This Row],[Chemistry Score]]>=75,"A-",Table1[[#This Row],[Chemistry Score]]>=70,"B+",Table1[[#This Row],[Chemistry Score]]>=65,"B",Table1[[#This Row],[Chemistry Score]]>=60,"B-",Table1[[#This Row],[Chemistry Score]]>=50,"C",Table1[[#This Row],[Chemistry Score]]>=40,"D",Table1[[#This Row],[Chemistry Score]]<40,"F")} -> B+ | T11: 67 | U11: {=_xlfn.IFS(Table1[[#This Row],[Biology Score]]>=90,"A+",Table1[[#This Row],[Biology Score]]>=80,"A", Table1[[#This Row],[Biology Score]]>=75,"A-",Table1[[#This Row],[Biology Score]]>=70,"B+",Table1[[#This Row],[Biology Score]]>=65,"B",Table1[[#This Row],[Biology Score]]>=60,"B-",Table1[[#This Row],[Biology Score]]>=50,"C",Table1[[#This Row],[Biology Score]]>=40,"D",Table1[[#This Row],[Biology Score]]<40,"F")} -> B | V11: 71 | W11: {=_xlfn.IFS(Table1[[#This Row],[English Score]]>=90,"A+",Table1[[#This Row],[English Score]]>=80,"A", Table1[[#This Row],[English Score]]>=75,"A-",Table1[[#This Row],[English Score]]>=70,"B+",Table1[[#This Row],[English Score]]>=65,"B",Table1[[#This Row],[English Score]]>=60,"B-",Table1[[#This Row],[English Score]]>=50,"C",Table1[[#This Row],[English Score]]>=40,"D",Table1[[#This Row],[English Score]]<40,"F")} -> B+ | X11: 73 | Y11: {=_xlfn.IFS(Table1[[#This Row],[Geography Score]]>=90,"A+",Table1[[#This Row],[Geography Score]]>=80,"A", Table1[[#This Row],[Geography Score]]>=75,"A-",Table1[[#This Row],[Geography Score]]>=70,"B+",Table1[[#This Row],[Geography Score]]>=65,"B",Table1[[#This Row],[Geography Score]]>=60,"B-",Table1[[#This Row],[Geography Score]]>=50,"C",Table1[[#This Row],[Geography Score]]>=40,"D",Table1[[#This Row],[Geography Score]]<40,"F")} -> B+ | Z11: =SUM(Table1[[#This Row],[Math Score]],Table1[[#This Row],[History Score]],Table1[[#This Row],[Physics Score]],Table1[[#This Row],[Chemistry Score]],Table1[[#This Row],[Biology Score]],Table1[[#This Row],[English Score]],Table1[[#This Row],[Geography Score]]) -> 537 | AA11: =AVERAGE(Table1[[#This Row],[Math Score]],Table1[[#This Row],[History Score]],Table1[[#This Row],[Physics Score]],Table1[[#This Row],[Chemistry Score]],Table1[[#This Row],[Biology Score]],Table1[[#This Row],[English Score]],Table1[[#This Row],[Geography Score]]) -> 76.714286 | AB11: =_xlfn.IFS(Table1[[#This Row],[Average Score]]>=90,"A+",Table1[[#This Row],[Average Score]]>=80,"A", Table1[[#This Row],[Average Score]]>=75,"A-",Table1[[#This Row],[Average Score]]>=70,"B+",Table1[[#This Row],[Average Score]]>=65,"B",Table1[[#This Row],[Average Score]]>=60,"B-",Table1[[#This Row],[Average Score]]>=50,"C",Table1[[#This Row],[Average Score]]>=40,"D",Table1[[#This Row],[Average Score]]<40,"F") -> A- | AC11: =RANK(AA11,$AA$2:$AA$2001,0) -> 1553 | AD11: =_xlfn.IFS(Table1[[#This Row],[Absence Days]]<3,"Excellent",Table1[[#This Row],[Absence Days]]<=6,"Good",Table1[[#This Row],[Absence Days]]>6,"Poor") -> Good
A12: 11 | B12: Gabrielle | C12: White | D12: =_xlfn.TEXTJOIN(" ",TRUE,Table1[[#This Row],[First Name]:[Last Name]]) -> Gabrielle White | E12: gabrielle.white.11@gslingacademy.com | F12: Female | G12: =PROPER(Table1[[#This Row],[Part Time Job]]) -> False | H12: 2 | I12: =PROPER(Table1[[#This Row],[Extracurricular Activities]]) -> False | J12: 7 | K12: Teacher | L12: 65 | M12: {=_xlfn.IFS(Table1[[#This Row],[Math Score]]>=90,"A+",Table1[[#This Row],[Math Score]]>=80,"A", Table1[[#This Row],[Math Score]]>=75,"A-",Table1[[#This Row],[Math Score]]>=70,"B+",Table1[[#This Row],[Math Score]]>=65,"B",Table1[[#This Row],[Math Score]]>=60,"B-",Table1[[#This Row],[Math Score]]>=50,"C",Table1[[#This Row],[Math Score]]>=40,"D",Table1[[#This Row],[Math Score]]<40,"F")} -> B | N12: 60 | O12: {=_xlfn.IFS(Table1[[#This Row],[History Score]]>=90,"A+",Table1[[#This Row],[History Score]]>=80,"A", Table1[[#This Row],[History Score]]>=75,"A-",Table1[[#This Row],[History Score]]>=70,"B+",Table1[[#This Row],[History Score]]>=65,"B",Table1[[#This Row],[History Score]]>=60,"B-",Table1[[#This Row],[History Score]]>=50,"C",Table1[[#This Row],[History Score]]>=40,"D",Table1[[#This Row],[History Score]]<40,"F")} -> B- | P12: 97 | Q12: {=_xlfn.IFS(Table1[[#This Row],[Physics Score]]>=90,"A+",Table1[[#This Row],[Physics Score]]>=80,"A", Table1[[#This Row],[Physics Score]]>=75,"A-",Table1[[#This Row],[Physics Score]]>=70,"B+",Table1[[#This Row],[Physics Score]]>=65,"B",Table1[[#This Row],[Physics Score]]>=60,"B-",Table1[[#This Row],[Physics Score]]>=50,"C",Table1[[#This Row],[Physics Score]]>=40,"D",Table1[[#This Row],[Physics Score]]<40,"F")} -> A+ | R12: 94 | S12: {=_xlfn.IFS(Table1[[#This Row],[Chemistry Score]]>=90,"A+",Table1[[#This Row],[Chemistry Score]]>=80,"A", Table1[[#This Row],[Chemistry Score]]>=75,"A-",Table1[[#This Row],[Chemistry Score]]>=70,"B+",Table1[[#This Row],[Chemistry Score]]>=65,"B",Table1[[#This Row],[Chemistry Score]]>=60,"B-",Table1[[#This Row],[Chemistry Score]]>=50,"C",Table1[[#This Row],[Chemistry Score]]>=40,"D",Table1[[#This Row],[Chemistry Score]]<40,"F")} -> A+ | T12: 71 | U12: {=_xlfn.IFS(Table1[[#This Row],[Biology Score]]>=90,"A+",Table1[[#This Row],[Biology Score]]>=80,"A", Table1[[#This Row],[Biology Score]]>=75,"A-",Table1[[#This Row],[Biology Score]]>=70,"B+",Table1[[#This Row],[Biology Score]]>=65,"B",Table1[[#This Row],[Biology Score]]>=60,"B-",Table1[[#This Row],[Biology Score]]>=50,"C",Table1[[#This Row],[Biology Score]]>=40,"D",Table1[[#This Row],[Biology Score]]<40,"F")} -> B+ | V12: 81 | W12: {=_xlfn.IFS(Table1[[#This Row],[English Score]]>=90,"A+",Table1[[#This Row],[English Score]]>=80,"A", Table1[[#This Row],[English Score]]>=75,"A-",Table1[[#This Row],[English Score]]>=70,"B+",Table1[[#This Row],[English Score]]>=65,"B",Table1[[#This Row],[English Score]]>=60,"B-",Table1[[#This Row],[English Score]]>=50,"C",Table1[[#This Row],[English Score]]>=40,"D",Table1[[#This Row],[English Score]]<40,"F")} -> A | X12: 66 | Y12: {=_xlfn.IFS(Table1[[#This Row],[Geography Score]]>=90,"A+",Table1[[#This Row],[Geography Score]]>=80,"A", Table1[[#This Row],[Geography Score]]>=75,"A-",Table1[[#This Row],[Geography Score]]>=70,"B+",Table1[[#This Row],[Geography Score]]>=65,"B",Table1[[#This Row],[Geography Score]]>=60,"B-",Table1[[#This Row],[Geography Score]]>=50,"C",Table1[[#This Row],[Geography Score]]>=40,"D",Table1[[#This Row],[Geography Score]]<40,"F")} -> B | Z12: =SUM(Table1[[#This Row],[Math Score]],Table1[[#This Row],[History Score]],Table1[[#This Row],[Physics Score]],Table1[[#This Row],[Chemistry Score]],Table1[[#This Row],[Biology Score]],Table1[[#This Row],[English Score]],Table1[[#This Row],[Geography Score]]) -> 534 | AA12: =AVERAGE(Table1[[#This Row],[Math Score]],Table1[[#This Row],[History Score]],Table1[[#This Row],[Physics Score]],Table1[[#This Row],[Chemistry Score]],Table1[[#This Row],[Biology Score]],Table1[[#This Row],[English Score]],Table1[[#This Row],[Geography Score]]) -> 76.285714 | AB12: =_xlfn.IFS(Table1[[#This Row],[Average Score]]>=90,"A+",Table1[[#This Row],[Average Score]]>=80,"A", Table1[[#This Row],[Average Score]]>=75,"A-",Table1[[#This Row],[Average Score]]>=70,"B+",Table1[[#This Row],[Average Score]]>=65,"B",Table1[[#This Row],[Average Score]]>=60,"B-",Table1[[#This Row],[Average Score]]>=50,"C",Table1[[#This Row],[Average Score]]>=40,"D",Table1[[#This Row],[Average Score]]<40,"F") -> A- | AC12: =RANK(AA12,$AA$2:$AA$2001,0) -> 1595 | AD12: =_xlfn.IFS(Table1[[#This Row],[Absence Days]]<3,"Excellent",Table1[[#This Row],[Absence Days]]<=6,"Good",Table1[[#This Row],[Absence Days]]>6,"Poor") -> Excellent
A13: 12 | B13: Clinton | C13: Randolph | D13: =_xlfn.TEXTJOIN(" ",TRUE,Table1[[#This Row],[First Name]:[Last Name]]) -> Clinton Randolph | E13: clinton.randolph.12@gslingacademy.com | F13: Male | G13: =PROPER(Table1[[#This Row],[Part Time Job]]) -> False | H13: 1 | I13: =PROPER(Table1[[#This Row],[Extracurricular Activities]]) -> False | J13: 7 | K13: Unknown | L13: 80 | M13: {=_xlfn.IFS(Table1[[#This Row],[Math Score]]>=90,"A+",Table1[[#This Row],[Math Score]]>=80,"A", Table1[[#This Row],[Math Score]]>=75,"A-",Table1[[#This Row],[Math Score]]>=70,"B+",Table1[[#This Row],[Math Score]]>=65,"B",Table1[[#This Row],[Math Score]]>=60,"B-",Table1[[#This Row],[Math Score]]>=50,"C",Table1[[#This Row],[Math Score]]>=40,"D",Table1[[#This Row],[Math Score]]<40,"F")} -> A | N13: 61 | O13: {=_xlfn.IFS(Table1[[#This Row],[History Score]]>=90,"A+",Table1[[#This Row],[History Score]]>=80,"A", Table1[[#This Row],[History Score]]>=75,"A-",Table1[[#This Row],[History Score]]>=70,"B+",Table1[[#This Row],[History Score]]>=65,"B",Table1[[#This Row],[History Score]]>=60,"B-",Table1[[#This Row],[History Score]]>=50,"C",Table1[[#This Row],[History Score]]>=40,"D",Table1[[#This Row],[History Score]]<40,"F")} -> B- | P13: 100 | Q13: {=_xlfn.IFS(Table1[[#This Row],[Physics Score]]>=90,"A+",Table1[[#This Row],[Physics Score]]>=80,"A", Table1[[#This Row],[Physics Score]]>=75,"A-",Table1[[#This Row],[Physics Score]]>=70,"B+",Table1[[#This Row],[Physics Score]]>=65,"B",Table1[[#This Row],[Physics Score]]>=60,"B-",Table1[[#This Row],[Physics Score]]>=50,"C",Table1[[#This Row],[Physics Score]]>=40,"D",Table1[[#This Row],[Physics Score]]<40,"F")} -> A+ | R13: 65 | S13: {=_xlfn.IFS(Table1[[#This Row],[Chemistry Score]]>=90,"A+",Table1[[#This Row],[Chemistry Score]]>=80,"A", Table1[[#This Row],[Chemistry Score]]>=75,"A-",Table1[[#This Row],[Chemistry Score]]>=70,"B+",Table1[[#This Row],[Chemistry Score]]>=65,"B",Table1[[#This Row],[Chemistry Score]]>=60,"B-",Table1[[#This Row],[Chemistry Score]]>=50,"C",Table1[[#This Row],[Chemistry Score]]>=40,"D",Table1[[#This Row],[Chemistry Score]]<40,"F")} -> B | T13: 87 | U13: {=_xlfn.IFS(Table1[[#This Row],[Biology Score]]>=90,"A+",Table1[[#This Row],[Biology Score]]>=80,"A", Table1[[#This Row],[Biology Score]]>=75,"A-",Table1[[#This Row],[Biology Score]]>=70,"B+",Table1[[#This Row],[Biology Score]]>=65,"B",Table1[[#This Row],[Biology Score]]>=60,"B-",Table1[[#This Row],[Biology Score]]>=50,"C",Table1[[#This Row],[Biology Score]]>=40,"D",Table1[[#This Row],[Biology Score]]<40,"F")} -> A | V13: 64 | W13: {=_xlfn.IFS(Table1[[#This Row],[English Score]]>=90,"A+",Table1[[#This Row],[English Score]]>=80,"A", Table1[[#This Row],[English Score]]>=75,"A-",Table1[[#This Row],[English Score]]>=70,"B+",Table1[[#This Row],[English Score]]>=65,"B",Table1[[#This Row],[English Score]]>=60,"B-",Table1[[#This Row],[English Score]]>=50,"C",Table1[[#This Row],[English Score]]>=40,"D",Table1[[#This Row],[English Score]]<40,"F")} -> B- | X13: 61 | Y13: {=_xlfn.IFS(Table1[[#This Row],[Geography Score]]>=90,"A+",Table1[[#This Row],[Geography Score]]>=80,"A", Table1[[#This Row],[Geography Score]]>=75,"A-",Table1[[#This Row],[Geography Score]]>=70,"B+",Table1[[#This Row],[Geography Score]]>=65,"B",Table1[[#This Row],[Geography Score]]>=60,"B-",Table1[[#This Row],[Geography Score]]>=50,"C",Table1[[#This Row],[Geography Score]]>=40,"D",Table1[[#This Row],[Geography Score]]<40,"F")} -> B- | Z13: =SUM(Table1[[#This Row],[Math Score]],Table1[[#This Row],[History Score]],Table1[[#This Row],[Physics Score]],Table1[[#This Row],[Chemistry Score]],Table1[[#This Row],[Biology Score]],Table1[[#This Row],[English Score]],Table1[[#This Row],[Geography Score]]) -> 518 | AA13: =AVERAGE(Table1[[#This Row],[Math Score]],Table1[[#This Row],[History Score]],Table1[[#This Row],[Physics Score]],Table1[[#This Row],[Chemistry Score]],Table1[[#This Row],[Biology Score]],Table1[[#This Row],[English Score]],Table1[[#This Row],[Geography Score]]) -> 74 | AB13: =_xlfn.IFS(Table1[[#This Row],[Average Score]]>=90,"A+",Table1[[#This Row],[Average Score]]>=80,"A", Table1[[#This Row],[Average Score]]>=75,"A-",Table1[[#This Row],[Average Score]]>=70,"B+",Table1[[#This Row],[Average Score]]>=65,"B",Table1[[#This Row],[Average Score]]>=60,"B-",Table1[[#This Row],[Average Score]]>=50,"C",Table1[[#This Row],[Average Score]]>=40,"D",Table1[[#This Row],[Average Score]]<40,"F") -> B+ | AC13: =RANK(AA13,$AA$2:$AA$2001,0) -> 1775 | AD13: =_xlfn.IFS(Table1[[#This Row],[Absence Days]]<3,"Excellent",Table1[[#This Row],[Absence Days]]<=6,"Good",Table1[[#This Row],[Absence Days]]>6,"Poor") -> Excellent
